Workbook

Sheet Summary
A1: Robot build costs
A2: Desktop robot arm, tracked rover and hexapod. Canadian dollars, prices checked 26 Oct 2026 at Canadian retailers (some US stores where nothing Canadian was found). Shipping is not included. Change any blue cell and every total updates.
A5: Assumptions
B7: HST (New Brunswick) | C7: 0.15 | D7: Harmonized sales tax
B8: USD to CAD | C8: 1.3993 | D8: Bank of Canada, 23 Oct 2026
B9: PETG price per kg | C9: =Prices!H54 -> 14.99 | D9: Sunlu PETG 1 kg at Canada Computers; Prusament PETG is on the Prices sheet
B10: Electricity ($/kWh) | C10: =Prices!H19 -> 0.1584 | D10: NB Power residential energy charge
B11: Printer power while printing PETG (kW) | C11: 0.09 | D11: Assumption: MK3S average with the bed at 80-90 °C
A13: What each robot costs
B14: Robot | C14: Bought parts | D14: PETG | E14: Electricity | F14: Total before tax | G14: Total with HST | H14: Budget total with HST
B15: Desktop robot arm | C15: =SUM(Arm!J5:J36) -> 263.15 | D15: =Arm!J39 -> 14.99 | E15: =Arm!J40 -> 0.491832 | F15: =SUM(C15:E15) -> 278.63183 | G15: =F15*(1+$C$7) -> 320.42661 | H15: =Arm!K42*(1+$C$7) -> 274.87525
B16: Tracked rover | C16: =SUM(Rover!J5:J39) -> 324.39919 | D16: =Rover!J42 -> 14.99 | E16: =Rover!J43 -> 0.470448 | F16: =SUM(C16:E16) -> 339.85964 | G16: =F16*(1+$C$7) -> 390.83858 | H16: =Rover!K45*(1+$C$7) -> 335.97572
B17: Hexapod | C17: =SUM(Hexapod!J5:J35) -> 412.57429 | D17: =Hexapod!J38 -> 14.99 | E17: =Hexapod!J39 -> 0.4504896 | F17: =SUM(C17:E17) -> 428.01478 | G17: =F17*(1+$C$7) -> 492.217 | H17: =Hexapod!K41*(1+$C$7) -> 388.59871
B18: All three, bought together | C18: =SUM('All three'!G5:G76) -> 833.96414 | D18: ='All three'!G78 -> 29.98 | E18: ='All three'!G79 -> 1.4127696 | F18: =SUM(C18:E18) -> 865.35691 | G18: =F18*(1+$C$7) -> 995.16045 | H18: ='All three'!H81*(1+$C$7) -> 804.85893
B19: Saving from shared packs | G19: =SUM(G15:G17)-G18 -> 208.32174
B21: Value of the parts each robot actually uses (its share of every pack)
B22: Robot | C22: Parts used | D22: PETG used | E22: Electricity | F22: Total before tax | G22: Total with HST
B23: Desktop robot arm | C23: =SUM(Arm!F5:F36) -> 173.655 | D23: =Arm!F39 -> 6.26582 | E23: =Arm!F40 -> 0.491832 | F23: =SUM(C23:E23) -> 180.41265 | G23: =F23*(1+$C$7) -> 207.47455
B24: Tracked rover | C24: =SUM(Rover!F5:F39) -> 192.86527 | D24: =Rover!F42 -> 5.02165 | E24: =Rover!F43 -> 0.470448 | F24: =SUM(C24:E24) -> 198.35737 | G24: =F24*(1+$C$7) -> 228.11097
B25: Hexapod | C25: =SUM(Hexapod!F5:F35) -> 304.94797 | D25: =Hexapod!F38 -> 5.81612 | E25: =Hexapod!F39 -> 0.4504896 | F25: =SUM(C25:E25) -> 311.21458 | G25: =F25*(1+$C$7) -> 357.89677
B27: • Not counted: the Logitech Brio 4K you already own (C$249.99 new at Canada Computers), shipping, and tools.
B28: • Tools you may need: soldering iron (also sets the rover's heat-set inserts), hex keys 1.5 and 2.5 mm, small Phillips screwdriver, multimeter, calipers, needle file, hacksaw and file for the rover's steel plates.
B29: • Budget total: the same build with the cheapest price found per item (servos direct from Waveshare, and so on).
B30: • Prices with confidence 'estimate' on the Prices sheet are typical store prices where no listing could be read; check them before ordering. Amazon.ca was not readable by the price search and is often cheaper for multi-packs.
B31: • PETG and print hours: arm from its round-3 slices (the new claw is heavier); rover from its round-2 slices; hexapod estimated. They change with each design round.

Sheet Prices
A1: Prices (CAD, before tax and shipping)
A2: Checked 26 Oct 2026. Blue cells are inputs you can change; everything else recalculates. USD prices convert at the rate on the Summary sheet. Confidence: high = price seen on the product page; medium = search snippet, unclear variant or a typical store price; estimate = no price could be read, a typical price is used.
A4: Key | B4: Item | C4: Listing | D4: Retailer | E4: Pack qty | F4: Pack price | G4: Currency | H4: Pack price (CAD) | I4: Unit price (CAD) | J4: Budget option | K4: Budget pack qty | L4: Budget pack (CAD) | M4: Confidence | N4: Notes | O4: Buy link | P4: Budget link
A5: breadboard | B5: Mini breadboard | C5: Mini breadboard 170 tie-point, self-adhesive (white) | D5: Canada Robotix | E5: 1 | F5: 2.99 | G5: CAD | H5: =IF(G5="USD",F5*Summary!$C$8,F5) -> 2.99 | I5: =H5/E5 -> 2.99 | M5: high | N5: Need 1 (R). In stock (50+). RobotShop costs more: pair $6.30 (not stocked, ordered on demand) or single $7.50. | O5: https://www.canadarobotix.com/products/941
A6: brio | B6: Logitech Brio 4K | C6: Logitech BRIO Webcam with 4K Ultra HD Video (960-001105) | D6: Canada Computers | E6: 1 | F6: 249.99 | G6: CAD | H6: =IF(G6="USD",F6*Summary!$C$8,F6) -> 249.99 | I6: =H6/E6 -> 249.99 | M6: high | N6: Reference only (already owned). Sold out online and at all stores. Staples.ca lists the renamed Logitech 4K Pro Webcam (960-001390) at C$249.99. Logitech.com/en-ca could not be read. | O6: https://www.canadacomputers.com/en/webcam/105281/logitech-brio-webcam-with-4k-ultra-hd-video-black-960-001105.html
A7: capkit.1000uF | B7: 1000 µF capacitor | C7: SparkFun electrolytic decoupling capacitor 1000 uF / 25 V (single, COM-08982) | D7: RobotShop (Canada) | E7: 1 | F7: 0.71 | G7: CAD | H7: =IF(G7="USD",F7*Summary!$C$8,F7) -> 0.71 | I7: =H7/E7 -> 0.71 | M7: high | N7: capkit part 1 of 2 (sum capkit.* rows). Need 3 (A1 + H2) = $2.13. Pack size not printed on the page; SparkFun COM-08982 is sold singly and RobotShop's 10-pack lists '10 x COM-08982' ($7.28). 25 V exceeds the 10-16 V spec (fine; can is larger). No readable assortment covered 1000 uF cheaper. Alt: SparkFun Capacitor Kit 115 pcs (10x100 uF, 10x1000 uF, 25x100 nF, etc.) CA$16.43 at RobotShop covers capkit + ceramickit. | O7: https://ca.robotshop.com/products/sparkfun-electrolytic-decoupling-capacitors-1000uf-25v
A8: capkit.100uF | B8: 100 µF capacitor | C8: SparkFun electrolytic decoupling capacitor 100 uF / 25 V (single) | D8: RobotShop (Canada) | E8: 1 | F8: 0.71 | G8: CAD | H8: =IF(G8="USD",F8*Summary!$C$8,F8) -> 0.71 | I8: =H8/E8 -> 0.71 | M8: high | N8: capkit part 2 of 2. Need 1 (R). Pack size not printed (SparkFun part is a single). 25 V >= 16 V spec. Alt: Canada Robotix 100 uF 50 V 2-pack $0.99. | O8: https://ca.robotshop.com/products/sparkfun-electrolytic-decoupling-capacitors-100uf-25v
A9: cells18650 | B9: 18650 cell, protected | C9: Panasonic NCR18650B 18650 Button Top Protected Rechargeable Battery | D9: FlashLight World (Magog QC, Canada) | E9: 1 | F9: 29.95 | G9: CAD | H9: =IF(G9="USD",F9*Summary!$C$8,F9) -> 29.95 | I9: =H9/E9 -> 29.95 | J9: LG MJ1 INR18650-MJ1 3500mAh protected button top, 68.8 mm (sold singly) (Illumn (illumn.com)) | K9: 1 | L9: =7.49*Summary!$C$8 -> 10.480757 | M9: high | N9: Checked 2026-10-26. Price per cell; og:price:currency CAD. Spec table: protected (PCB), button top, 3400 mAh nominal (3350 mAh datasheet). Ships from Canada (free shipping to most regions). Final sale. flashlightworld.ca redirects to this .com domain. Cheaper option: Illumn KeepPower 3500 mAh NCR18650GA protected button top, 9.99 USD, https://illumn.com/18650-keeppower-3500mah-sanyo-ncr18650ga-protected-button-top.html, but Illumn is based in San Jose, USA (prices in USD), not in Canada. | O9: https://www.flashlightworld.com/collections/18650-batteries/products/panasonic-ncr-18650b-3400mah-4-9a-protected-button-top-battery | P9: https://illumn.com/18650-lg-mj1-inr18650-mj1-high-discharge-protected-button-top.html
A10: ceramickit | B10: 100 nF capacitors | C10: Ceramic capacitor 0.1 uF (100 nF) 50 V, 5 pcs | D10: Canada Robotix | E10: 5 | F10: 1.99 | G10: CAD | H10: =IF(G10="USD",F10*Summary!$C$8,F10) -> 1.99 | I10: =H10/E10 -> 0.398 | M10: high | N10: Need 4 (R3 + H1): one pack. In stock (50+). Alt: RobotShop SparkFun 0.1 uF ceramic $0.46 each (pack size not stated). | O10: https://www.canadarobotix.com/products/905
A11: charger18650 | B11: Li-ion charger, 2 bays | C11: Xtar X2 Li-ion/Ni-MH Dual Bay Smart Quick Charger (updated) | D11: Illumn (illumn.com) | E11: 1 | F11: 14.5 | G11: USD | H11: =IF(G11="USD",F11*Summary!$C$8,F11) -> 20.28985 | I11: =H11/E11 -> 20.28985 | M11: high | N11: In stock; includes AC wall plug; 2 A x1 / 1 A x2; fits up to protected 21700. US store (see cells18650). Canadian-stock alternative: Canada Robotix Nitecore D2 Digicharger #3049 C$39.99 (5 left). | O11: https://illumn.com/chargers/xtar-x2-li-ion-ni-mh-dual-bay-smart-quick-charger.html
A12: consumables.ca | B12: CA glue | C12: Gorilla Super Glue 2-pack (CA glue) | D12: Princess Auto | E12: 2 | F12: 9.99 | G12: CAD | H12: =IF(G12="USD",F12*Summary!$C$8,F12) -> 9.99 | I12: =H12/E12 -> 4.995 | M12: high | N12: consumables part 3 of 4. Container size listed as 0.2 oz. IN-STORE ONLY (no shipping). Home Depot Canada CA-glue pages showed no price. | O12: https://www.princessauto.com/en/product/PA0008551582
A13: consumables.foamtape | B13: Mounting tape | C13: Scotch-Mount double-sided mounting tape 1 x 60 in | D13: Princess Auto | E13: 1 | F13: 9.99 | G13: CAD | H13: =IF(G13="USD",F13*Summary!$C$8,F13) -> 9.99 | I13: =H13/E13 -> 9.99 | M13: high | N13: consumables part 1 of 4 (shared A/R/H). Page says double-sided Scotch-Mount; foam construction not stated. Available. | O13: https://www.princessauto.com/en/product/PA0009298993
A14: consumables.hotglue | B14: Hot-glue sticks | C14: Mini glue gun sticks 5/16 x 4 in, 12 pcs | D14: Princess Auto | E14: 12 | F14: 6.99 | G14: CAD | H14: =IF(G14="USD",F14*Summary!$C$8,F14) -> 6.99 | I14: =H14/E14 -> 0.5825 | M14: high | N14: consumables part 2 of 4. Available. | O14: https://www.princessauto.com/en/product/PA0008369621
A15: consumables.threadlocker | B15: Threadlocker (blue) | C15: Loctite 242 threadlocker, blue (medium strength), 6 mL | D15: RobotShop (Canada) | E15: 1 | F15: 11.41 | G15: CAD | H15: =IF(G15="USD",F15*Summary!$C$8,F15) -> 11.41 | I15: =H15/E15 -> 11.41 | M15: high | N15: consumables part 4 of 4. Alt: Home Depot Canada Permatex Blue 10 mL $15.98; Princess Auto Permatex blue gel 10 g $17.99 (in-store only). | O15: https://ca.robotshop.com/products/loctite-threadlocker-blue-242-6ml
A16: dcjack | B16: DC jack 5.5 × 2.1 | C16: Metal Panel Mount 2.1mm DC Barrel Jack, 5.5 x 2.1 mm (CON-152) | D16: BC Robotics | E16: 1 | F16: 1.95 | G16: CAD | H16: =IF(G16="USD",F16*Summary!$C$8,F16) -> 1.95 | I16: =H16/E16 -> 1.95 | M16: high | N16: In stock. 8 mm hole, panels up to 2.25 mm thick, solder tabs. Thread/nut and current rating not stated. | O16: https://bc-robotics.com/shop/metal-panel-mount-2-1mm-dc-barrel-jack/
A17: dcswitch | B17: Inline DC switch | C17: Inline Power Switch - 2.1mm DC Barrel Plug, 5.5 x 2.1 plug-to-jack, 300 mm (CAB-017) | D17: BC Robotics | E17: 1 | F17: 4.95 | G17: CAD | H17: =IF(G17="USD",F17*Summary!$C$8,F17) -> 4.95 | I17: =H17/E17 -> 4.95 | M17: high | N17: The only readable listing that states >= 5 A: 5 A at 12 V or less (2 A at 120 V). OUT OF STOCK. In-stock alternative: RobotShop CA SparkFun 3-inch Barrel Jack 2.1mm Power Switch C$5.00 (RB-Spa-790), no current rating stated. The Universal-Solder inline switch (C$1.99) is rated under 3 A, which fails the spec. | O17: https://bc-robotics.com/shop/inline-power-switch-2-1mm-barrel-plug/
A18: dowel2x24 | B18: Ø2 mm steel rod 100 mm | C18: 2 mm diameter shaft, 100 mm long, material not stated (cut into 24 mm pins) | D18: BC Robotics | E18: 1 | F18: 0.95 | G18: CAD | H18: =IF(G18="USD",F18*Summary!$C$8,F18) -> 0.95 | I18: =H18/E18 -> 0.95 | M18: high | N18: Need 70 pins x 24 mm (R): 4 pins per rod -> 18 rods = $17.10 plus cutting/deburring (~$0.24 per pin). Material and tolerance not stated ('Generic'). In stock. Accu sells 2 x 24 mm DIN 7 dowel pins (HDP-2-24-A1, A1 stainless, m6) but prices aren't readable; McMaster likewise. | O18: https://bc-robotics.com/shop/2-x-100mm-shaft/
A19: electricity | B19: Electricity (NB Power) | C19: NB Power residential energy charge, per kWh (15.39 c base + 0.45 c variance account charge) | D19: NB Power | E19: 1 | F19: 0.1584 | G19: CAD | H19: =IF(G19="USD",F19*Summary!$C$8,F19) -> 0.1584 | I19: =H19/E19 -> 0.1584 | M19: high | N19: 15.84 c/kWh for all kWh, effective 2026-04-14. pack_qty = 1 kWh. Monthly service charge $30.82 urban / $33.82 rural/seasonal (not per kWh). HST extra. | O19: https://nbpower.com/en/products-services/residential/rates
A20: esp32 | B20: ESP32 DevKit | C20: ESP32 Devkit ESP-WROOM-32, 4MB, CP210x USB-UART, micro-USB (SKU 26232) | D20: Universal-Solder (CANADUINO) | E20: 1 | F20: 9.86 | G20: CAD | H20: =IF(G20="USD",F20*Summary!$C$8,F20) -> 9.86 | I20: =H20/E20 -> 9.86 | M20: high | N20: Price is the 3-9 qty tier (C$10.95 single); need 3 -> C$29.58. In stock. Pin count (30 vs 38) and whether headers are soldered are NOT stated; check photos before ordering. Alternatives (pin count also not stated): BC Robotics ESP32 Development Board C$12.95 (CP2102, in stock); Canada Robotix #2594 C$12.99 (6 left). Amazon.ca blocks automated page reads, so no Amazon.ca prices could be checked. | O20: https://www.universal-solder.ca/product/esp32-devkit-esp-wroom-32-4mb-cp2101-usb-uart/
A21: flatbar | B21: 14 ga steel strip | C21: 14-gauge (1.9 mm) steel strip or sheet, small piece | D21: Princess Auto / Home Depot (typical) | E21: 1 | F21: 12 | G21: CAD | H21: =IF(G21="USD",F21*Summary!$C$8,F21) -> 12 | I21: =H21/E21 -> 12 | M21: estimate | N21: Estimate. Two 21 × 10 and two 14 × 8 mm plates are cut from it
A22: fuseholder | B22: Inline fuse holder | C22: 2 x Inline ATO/ATC Fuse Holder 18AWG (CAB-157, each incl. one 5A ATO fuse) + Littelfuse Japanese ATO assortment 5-pk (5/7.5/10/15/20A) | D22: BC Robotics + Partsource | E22: 2 | F22: 13.89 | G22: CAD | H22: =IF(G22="USD",F22*Summary!$C$8,F22) -> 13.89 | I22: =H22/E22 -> 6.945 | M22: high | N22: Two retailers. 2 holders x C$2.95 = C$5.90 (in stock, 300 mm 18AWG leads) + Partsource 009403001ZP assortment C$7.99 (https://partsource.ca/products/009403001zp-littelfuse-japanese-ato-fuse-assortment-5-pk) for the 7.5A blade. Total: 2 holders, 3 x 5A, 1 x 7.5A plus spares. unit_price = per holder incl. fuses. | O22: https://bc-robotics.com/shop/inline-ato-atc-fuse-holder-18awg/
A23: fx | B23: fx | C23: USD to CAD exchange rate (CAD per 1 USD) | D23: Pound Sterling Live (market close) | E23: 1 | F23: 1.4004 | G23: CAD | H23: =IF(G23="USD",F23*Summary!$C$8,F23) -> 1.4004 | I23: =H23/E23 -> 1.4004 | M23: high | N23: Close on Fri 2026-10-23, the latest available on 2026-10-26 (day mid 1.3994). Used for every USD conversion in this file. | O23: https://www.poundsterlinglive.com/history/USD-CAD-2026
A24: hcsr04 | B24: HC-SR04 sensor | C24: HC-SR04 Ultrasonic Sensor (JSumo, RB-Jsu-85) | D24: RobotShop CA | E24: 1 | F24: 4.93 | G24: CAD | H24: =IF(G24="USD",F24*Summary!$C$8,F24) -> 4.93 | I24: =H24/E24 -> 4.93 | M24: high | N24: In stock. Canada Robotix #1072 C$5.09. | O24: https://ca.robotshop.com/products/hc-sr04-ultrasonic-sensor
A25: heatshrink | B25: Heat-shrink kit | C25: ServoCity heat-shrink tubing assortment, 560 pcs in case | D25: RobotShop (Canada) | E25: 1 | F25: 12.84 | G25: CAD | H25: =IF(G25="USD",F25*Summary!$C$8,F25) -> 12.84 | I25: =H25/E25 -> 12.84 | M25: high | N25: Shared A/R/H. Page doesn't list the individual diameters/colours. | O25: https://ca.robotshop.com/products/servocity-heat-shrink-tubing-560pc-assortment-pack
A26: holder18650 | B26: 2 × 18650 holder | C26: 2 x 18650 Battery Holder, series 7.4 V, 6 in leads (BTC-033) | D26: BC Robotics | E26: 1 | F26: 1.95 | G26: CAD | H26: =IF(G26="USD",F26*Summary!$C$8,F26) -> 1.95 | I26: =H26/E26 -> 1.95 | M26: high | N26: In stock. Fit for protected cells (68.8-69 mm) is NOT stated; the holder body is 76.3 mm long. Alternatives: Canada Robotix #2914 C$2.99 (series); RobotShop CA SparkFun 2x18650 with wire leads C$2.79 (RB-Spa-2511). | O26: https://bc-robotics.com/shop/2-x-18650-battery-holder/
A27: hub1996 | B27: Pololu #1996 hub (2-pack) | C27: Universal Aluminum Mounting Hub (3mm Shaft, M3 Holes, 2-Pack) (SKU 1322) | D27: Canada Robotix | E27: 2 | F27: 7.69 | G27: CAD | H27: =IF(G27="USD",F27*Summary!$C$8,F27) -> 7.69 | I27: =H27/E27 -> 3.845 | M27: high | N27: Title matches Pololu #1996 (listing vendor shows 'Other'). In stock. Pololu direct is US$9.95 per 2-pack (= C$13.92). | O27: https://www.canadarobotix.com/products/1322
A28: inserts | B28: M3 heat-set inserts | C28: M3 knurled brass heat-set insert, per piece (4.2 OD x 5 mm; also 5x4 and 5x5 variants) | D28: Spool3D | E28: 1 | F28: 0.15 | G28: CAD | H28: =IF(G28="USD",F28*Summary!$C$8,F28) -> 0.15 | I28: =H28/E28 -> 0.15 | M28: high | N28: Need 4 (R) = $0.60. Same price shown for all variants; 10% off at 10+. Stock field blank. Shorter than the M3x5.7 class (closest is 4.2 x 5 mm). Alt: RobotShop 3D Printing Canada M3x5 heat-set insert 10-pack $5.95. | O28: https://spool3d.ca/m3-knurled-brass-threaded-insert/
A29: jumpers.ff | B29: Jumpers F-F | C29: ServoCity jumper wire F-F, 20 cm, multicolour, 40-pack | D29: RobotShop (Canada) | E29: 40 | F29: 5.7 | G29: CAD | H29: =IF(G29="USD",F29*Summary!$C$8,F29) -> 5.7 | I29: =H29/E29 -> 0.1425 | M29: high | N29: jumpers part 3 of 3. | O29: https://ca.robotshop.com/products/servocity-female-to-female-jumper-wire-multicolor-20cm-length-40-pack
A30: jumpers.mf | B30: Jumpers M-F | C30: ServoCity jumper wire M-F, 20 cm, multicolour, 40-pack | D30: RobotShop (Canada) | E30: 40 | F30: 5.7 | G30: CAD | H30: =IF(G30="USD",F30*Summary!$C$8,F30) -> 5.7 | I30: =H30/E30 -> 0.1425 | M30: high | N30: jumpers part 2 of 3. | O30: https://ca.robotshop.com/products/servocity-male-to-female-jumper-wire-multicolor-20cm-length-40-pack
A31: jumpers.mm | B31: Jumpers M-M | C31: ServoCity jumper wire M-M, 20 cm, multicolour, 40-pack | D31: RobotShop (Canada) | E31: 40 | F31: 5.7 | G31: CAD | H31: =IF(G31="USD",F31*Summary!$C$8,F31) -> 5.7 | I31: =H31/E31 -> 0.1425 | M31: high | N31: jumpers part 1 of 3: M-M + M-F + F-F 40-packs = 120 wires, $17.10 total. Canada Robotix 40-pin 20 cm ribbons are $6.99 each. | O31: https://ca.robotshop.com/products/servocity-male-to-male-jumper-wire-multicolor-20cm-length-40-pack
A32: lipo2s | B32: 2S LiPo ≈1000 mAh | C32: GNB Long Range 1100mAh 2S HV 60C LiPo, XT30 | D32: Rotor Village | E32: 1 | F32: 11.41 | G32: USD | H32: =IF(G32="USD",F32*Summary!$C$8,F32) -> 15.966013 | I32: =H32/E32 -> 15.966013 | M32: medium | N32: Closest in-stock match at a Canadian FPV shop; no 1000mAh 2S XT30 pack was found. Price from the 2S category listing (https://rotorvillage.ca/2-cell-2s-7-4v/), which the site displayed in USD (CAD price not shown); the product page could not be opened. LiHV pack (8.7 V full): charge in LiHV mode, or as standard LiPo for slightly less capacity. Other in-stock option: GNB 880mAh 2S HV 160C XT30 US$10.70. RobotShop CA and Canada Robotix carry no 2S XT30 LiPo. | O32: https://rotorvillage.ca/gnb-long-range-1100mah-2s-hv-60c-lipo-xt30/
A33: lipoalarm | B33: LiPo alarm | C33: LiPo Voltmeter & Buzzer, 1S-8S | D33: Rotor Village | E33: 1 | F33: 3.85 | G33: USD | H33: =IF(G33="USD",F33*Summary!$C$8,F33) -> 5.387305 | I33: =H33/E33 -> 5.387305 | M33: high | N33: 4 in stock. Page displayed USD; converted. Adjustable alarm threshold not stated. | O33: https://rotorvillage.ca/lipo-voltmeter-buzzer-1s-to-8s/
... A35: lipocharger | B35: 2S LiPo balance charger | C35: B3AC LiPo Balance Charger 18W, 2S/3S, AC input (HTRC/Huituo, RB-Hui-06) | D35: RobotShop CA | E35: 1 | F35: 28.57 | G35: CAD | H35: =IF(G35="USD",F35*Summary!$C$8,F35) -> 28.57 | I35: =H35/E35 -> 28.57 | M35: high | N35: In stock; built-in 100-240 VAC plug; 700 mA per cell; charges through the balance lead. Standard LiPo only (no LiHV mode). Upgrade: ToolkitRC M4AC 1-4S AC charger (has LiHV mode) at Rotor Village, $49.99 shown as CAD (5 in stock). | O35: https://ca.robotshop.com/products/b3ac-lipo-battery-charger-18w-us
A36: m17 | B36: M1.7 × 5 horn screws | C36: 750 Pcs Self Tapping Screws For Plastic And Metal M1.7 To M3 Phillips Pan Head Tiny Black Carbon Steel Micro Electronic Screws Assortment Kit Great For DIY Projects And Repairs | D36: Bearings Canada (Woodbridge ON) | E36: 50 | F36: 38.06 | G36: CAD | H36: =IF(G36="USD",F36*Summary!$C$8,F36) -> 38.06 | I36: =H36/E36 -> 0.7612 | J36: M1.7 × 5 self-tapping servo horn screws, pack of 100 (Amazon.ca / AliExpress (typical)) | K36: 100 | L36: 7 | M36: high | N36: Checked 2026-10-26. Sale price (list 76.14 CAD). Kit contains M1.7 x 5/6/8, M2 x 4/5/6, M2.3, M2.6 and M3, 50 of each; black carbon steel, Phillips pan head. Only 50 of the M1.7x5. No Canadian page found for a ~100-pack of M1.7x5 alone. Abra Electronics H-KIT-M1-ST (M1-M1.7 kit) page shows no price or quantities. Stock and shipping to NB not stated on the page. | O36: https://bearingscanada.com/products/750-pcs-self-tapping-screws-for-plastic-and-metal
A37: m25tap | B37: M2.5 × 6 self-tapping | C37: Phillips pan-head screw M2.5 x 6 mm, zinc-plated steel, 10-pack | D37: Canada Robotix | E37: 10 | F37: 1.49 | G37: CAD | H37: =IF(G37="USD",F37*Summary!$C$8,F37) -> 1.49 | I37: =H37/E37 -> 0.149 | M37: high | N37: Need 8 (H): one pack. Page does not say self-tapping (probably machine thread), so may not suit plain plastic holes. In stock (24). | O37: https://www.canadarobotix.com/products/843
A38: m2kit | B38: M2 screws + nuts | C38: M2 screw set: 20 x M2 x 10 mm Phillips machine screws + 20 M2 hex nuts | D38: BC Robotics | E38: 20 | F38: 2.95 | G38: CAD | H38: =IF(G38="USD",F38*Summary!$C$8,F38) -> 2.95 | I38: =H38/E38 -> 0.1475 | M38: high | N38: Need ~40 screws, 12 nuts, 36 washers (A, H): 2 sets ($5.90) give 40 screws + 40 nuts. Only one length (10 mm; spec 6-16 mm). Washers NOT included and not priced (BC lists an 'M2 Washer Set - 40 pcs' accessory). In stock. No readable M2 assortment with washers found. Alt: Canada Robotix M2x10 / M2x6 10-packs $1.49 and M2 nut 10-pack $1.49. | O38: https://bc-robotics.com/shop/m2-screw-set-40-pcs/
A39: m2nyloc | B39: M2 Nyloc nut | C39: M2 nylon-insert hex nut, stainless, per piece | D39: Spool3D | E39: 1 | F39: 0.35 | G39: CAD | H39: =IF(G39="USD",F39*Summary!$C$8,F39) -> 0.35 | I39: =H39/E39 -> 0.35 | M39: high | N39: Need 12 (H) = $4.20 (bulk discounts may apply). OUT OF STOCK when checked. RobotShop only has M2 plain hex nuts and M2.5 nyloc. | O39: https://spool3d.ca/m2-nylon-hex-nut-stainless-steel/
A40: m2washer | B40: M2 washers | C40: 3D Printing Canada Stainless Steel Metric Flat Washers M2 (10 Pack) | D40: RobotShop CA | E40: 10 | F40: 0.95 | G40: CAD | H40: =IF(G40="USD",F40*Summary!$C$8,F40) -> 0.95 | I40: =H40/E40 -> 0.095 | J40: M2 flat washers, pack of 100 (Hardware store / Amazon.ca (typical)) | K40: 100 | L40: 4 | M40: medium | N40: Checked 2026-10-26. Price from the page's og:price metadata (0.95 CAD); no visible price in the fetched text. 304 stainless; page says 1 mm thick; OD not stated. Pack of 10, not 100: buy 10 packs for 100 (~9.50 CAD). Stock not shown. | O40: https://ca.robotshop.com/products/3d-printing-canada-usa-3d-printing-canada-stainless-steel-metric-flat-washers-m2-10-pack
A41: m3ft40 | B41: M3 × 40 fully threaded 12.9 | C41: M3 × 40 socket head, class 12.9 alloy, fully threaded, pack of 10 | D41: Amazon.ca (typical) | E41: 10 | F41: 11 | G41: CAD | H41: =IF(G41="USD",F41*Summary!$C$8,F41) -> 11 | I41: =H41/E41 -> 1.1 | M41: estimate | N41: Estimate | O41: https://www.amazon.ca/
A42: m3ft50 | B42: M3 × 50 fully threaded 12.9 | C42: M3 × 50 socket head, class 12.9 alloy, fully threaded, pack of 10 | D42: Amazon.ca (typical) | E42: 10 | F42: 12 | G42: CAD | H42: =IF(G42="USD",F42*Summary!$C$8,F42) -> 12 | I42: =H42/E42 -> 1.2 | M42: estimate | N42: Estimate: a fully threaded 12.9 listing exists on Amazon.ca (Sutemribor, 55 pcs) but its price could not be read | O42: https://www.amazon.ca/
...

Sheet Arm
A1: Arm: bought parts and print cost
A2: Quantities come from the build guide's bill of materials. 'Value of parts used' counts only the share of each pack this robot uses; 'Cost to buy' is what you pay buying whole packs for this robot alone.
A4: Group | B4: Item | C4: Price key | D4: Qty | E4: Unit price | F4: Value of parts used | G4: Pack qty | H4: Packs to buy | I4: Pack price | J4: Cost to buy | K4: Budget cost | L4: Notes | M4: Where to buy
A5: Servos and boards | B5: MG996R metal-gear servo (base, shoulder, elbow) | C5: mg996r | D5: 3 | E5: =INDEX(Prices!$I$5:$I$82,MATCH(C5,Prices!$A$5:$A$82,0)) -> 8.95 | F5: =D5*E5 -> 26.85 | G5: =INDEX(Prices!$E$5:$E$82,MATCH(C5,Prices!$A$5:$A$82,0)) -> 1 | H5: =IF(D5<=0,0,CEILING(D5/G5,1)) -> 3 | I5: =INDEX(Prices!$H$5:$H$82,MATCH(C5,Prices!$A$5:$A$82,0)) -> 8.95 | J5: =H5*I5 -> 26.85 | K5: =IF(D5<=0,0,IF(ISNUMBER(INDEX(Prices!$L$5:$L$82,MATCH(C5,Prices!$A$5:$A$82,0))),CEILING(D5/INDEX(Prices!$K$5:$K$82,MATCH(C5,Prices!$A$5:$A$82,0)),1)*INDEX(Prices!$L$5:$L$82,MATCH(C5,Prices!$A$5:$A$82,0)),J5)) -> 20.947521 | L5: Keep the bags: Ø25 disc horn (base), double-arm horns | M5: =IFERROR(IF(INDEX(Prices!$O$5:$O$82,MATCH(C5,Prices!$A$5:$A$82,0))="","",HYPERLINK(INDEX(Prices!$O$5:$O$82,MATCH(C5,Prices!$A$5:$A$82,0)),INDEX(Prices!$D$5:$D$82,MATCH(C5,Prices!$A$5:$A$82,0)))),"") -> PiShop.ca
A6: Servos and boards | B6: MG90S metal-gear micro servo (wrist, claw) | C6: mg90s | D6: 2 | E6: =INDEX(Prices!$I$5:$I$82,MATCH(C6,Prices!$A$5:$A$82,0)) -> 6 | F6: =D6*E6 -> 12 | G6: =INDEX(Prices!$E$5:$E$82,MATCH(C6,Prices!$A$5:$A$82,0)) -> 1 | H6: =IF(D6<=0,0,CEILING(D6/G6,1)) -> 2 | I6: =INDEX(Prices!$H$5:$H$82,MATCH(C6,Prices!$A$5:$A$82,0)) -> 6 | J6: =H6*I6 -> 12 | K6: =IF(D6<=0,0,IF(ISNUMBER(INDEX(Prices!$L$5:$L$82,MATCH(C6,Prices!$A$5:$A$82,0))),CEILING(D6/INDEX(Prices!$K$5:$K$82,MATCH(C6,Prices!$A$5:$A$82,0)),1)*INDEX(Prices!$L$5:$L$82,MATCH(C6,Prices!$A$5:$A$82,0)),J6)) -> 6.43678 | M6: =IFERROR(IF(INDEX(Prices!$O$5:$O$82,MATCH(C6,Prices!$A$5:$A$82,0))="","",HYPERLINK(INDEX(Prices!$O$5:$O$82,MATCH(C6,Prices!$A$5:$A$82,0)),INDEX(Prices!$D$5:$D$82,MATCH(C6,Prices!$A$5:$A$82,0)))),"") -> BC Robotics
A7: Servos and boards | B7: ESP32 DevKit (38- or 30-pin) | C7: esp32 | D7: 1 | E7: =INDEX(Prices!$I$5:$I$82,MATCH(C7,Prices!$A$5:$A$82,0)) -> 9.86 | F7: =D7*E7 -> 9.86 | G7: =INDEX(Prices!$E$5:$E$82,MATCH(C7,Prices!$A$5:$A$82,0)) -> 1 | H7: =IF(D7<=0,0,CEILING(D7/G7,1)) -> 1 | I7: =INDEX(Prices!$H$5:$H$82,MATCH(C7,Prices!$A$5:$A$82,0)) -> 9.86 | J7: =H7*I7 -> 9.86 | K7: =IF(D7<=0,0,IF(ISNUMBER(INDEX(Prices!$L$5:$L$82,MATCH(C7,Prices!$A$5:$A$82,0))),CEILING(D7/INDEX(Prices!$K$5:$K$82,MATCH(C7,Prices!$A$5:$A$82,0)),1)*INDEX(Prices!$L$5:$L$82,MATCH(C7,Prices!$A$5:$A$82,0)),J7)) -> 9.86 | M7: =IFERROR(IF(INDEX(Prices!$O$5:$O$82,MATCH(C7,Prices!$A$5:$A$82,0))="","",HYPERLINK(INDEX(Prices!$O$5:$O$82,MATCH(C7,Prices!$A$5:$A$82,0)),INDEX(Prices!$D$5:$D$82,MATCH(C7,Prices!$A$5:$A$82,0)))),"") -> Universal-Solder (CANADUINO)
A8: Servos and boards | B8: Logitech Brio 4K webcam | C8: brio | D8: 0 | E8: =INDEX(Prices!$I$5:$I$82,MATCH(C8,Prices!$A$5:$A$82,0)) -> 249.99 | F8: =D8*E8 -> 0 | G8: =INDEX(Prices!$E$5:$E$82,MATCH(C8,Prices!$A$5:$A$82,0)) -> 1 | H8: =IF(D8<=0,0,CEILING(D8/G8,1)) -> 0 | I8: =INDEX(Prices!$H$5:$H$82,MATCH(C8,Prices!$A$5:$A$82,0)) -> 249.99 | J8: =H8*I8 -> 0 | K8: =IF(D8<=0,0,IF(ISNUMBER(INDEX(Prices!$L$5:$L$82,MATCH(C8,Prices!$A$5:$A$82,0))),CEILING(D8/INDEX(Prices!$K$5:$K$82,MATCH(C8,Prices!$A$5:$A$82,0)),1)*INDEX(Prices!$L$5:$L$82,MATCH(C8,Prices!$A$5:$A$82,0)),J8)) -> 0 | L8: You already own one: not counted | M8: =IFERROR(IF(INDEX(Prices!$O$5:$O$82,MATCH(C8,Prices!$A$5:$A$82,0))="","",HYPERLINK(INDEX(Prices!$O$5:$O$82,MATCH(C8,Prices!$A$5:$A$82,0)),INDEX(Prices!$D$5:$D$82,MATCH(C8,Prices!$A$5:$A$82,0)))),"") -> Canada Computers
A9: Power | B9: 6 V 5 A DC adapter, 5.5 × 2.1 mm, centre positive | C9: psu6v5a | D9: 1 | E9: =INDEX(Prices!$I$5:$I$82,MATCH(C9,Prices!$A$5:$A$82,0)) -> 27.13 | F9: =D9*E9 -> 27.13 | G9: =INDEX(Prices!$E$5:$E$82,MATCH(C9,Prices!$A$5:$A$82,0)) -> 1 | H9: =IF(D9<=0,0,CEILING(D9/G9,1)) -> 1 | I9: =INDEX(Prices!$H$5:$H$82,MATCH(C9,Prices!$A$5:$A$82,0)) -> 27.13 | J9: =H9*I9 -> 27.13 | K9: =IF(D9<=0,0,IF(ISNUMBER(INDEX(Prices!$L$5:$L$82,MATCH(C9,Prices!$A$5:$A$82,0))),CEILING(D9/INDEX(Prices!$K$5:$K$82,MATCH(C9,Prices!$A$5:$A$82,0)),1)*INDEX(Prices!$L$5:$L$82,MATCH(C9,Prices!$A$5:$A$82,0)),J9)) -> 27.13 | M9: =IFERROR(IF(INDEX(Prices!$O$5:$O$82,MATCH(C9,Prices!$A$5:$A$82,0))="","",HYPERLINK(INDEX(Prices!$O$5:$O$82,MATCH(C9,Prices!$A$5:$A$82,0)),INDEX(Prices!$D$5:$D$82,MATCH(C9,Prices!$A$5:$A$82,0)))),"") -> RobotShop CA
A10: Power | B10: 5.5 × 2.1 mm panel-mount DC jack | C10: dcjack | D10: 1 | E10: =INDEX(Prices!$I$5:$I$82,MATCH(C10,Prices!$A$5:$A$82,0)) -> 1.95 | F10: =D10*E10 -> 1.95 | G10: =INDEX(Prices!$E$5:$E$82,MATCH(C10,Prices!$A$5:$A$82,0)) -> 1 | H10: =IF(D10<=0,0,CEILING(D10/G10,1)) -> 1 | I10: =INDEX(Prices!$H$5:$H$82,MATCH(C10,Prices!$A$5:$A$82,0)) -> 1.95 | J10: =H10*I10 -> 1.95 | K10: =IF(D10<=0,0,IF(ISNUMBER(INDEX(Prices!$L$5:$L$82,MATCH(C10,Prices!$A$5:$A$82,0))),CEILING(D10/INDEX(Prices!$K$5:$K$82,MATCH(C10,Prices!$A$5:$A$82,0)),1)*INDEX(Prices!$L$5:$L$82,MATCH(C10,Prices!$A$5:$A$82,0)),J10)) -> 1.95 | M10: =IFERROR(IF(INDEX(Prices!$O$5:$O$82,MATCH(C10,Prices!$A$5:$A$82,0))="","",HYPERLINK(INDEX(Prices!$O$5:$O$82,MATCH(C10,Prices!$A$5:$A$82,0)),INDEX(Prices!$D$5:$D$82,MATCH(C10,Prices!$A$5:$A$82,0)))),"") -> BC Robotics
A11: Power | B11: Inline DC switch lead, 5.5 × 2.1 mm, ≥ 5 A (off switch) | C11: dcswitch | D11: 1 | E11: =INDEX(Prices!$I$5:$I$82,MATCH(C11,Prices!$A$5:$A$82,0)) -> 4.95 | F11: =D11*E11 -> 4.95 | G11: =INDEX(Prices!$E$5:$E$82,MATCH(C11,Prices!$A$5:$A$82,0)) -> 1 | H11: =IF(D11<=0,0,CEILING(D11/G11,1)) -> 1 | I11: =INDEX(Prices!$H$5:$H$82,MATCH(C11,Prices!$A$5:$A$82,0)) -> 4.95 | J11: =H11*I11 -> 4.95 | K11: =IF(D11<=0,0,IF(ISNUMBER(INDEX(Prices!$L$5:$L$82,MATCH(C11,Prices!$A$5:$A$82,0))),CEILING(D11/INDEX(Prices!$K$5:$K$82,MATCH(C11,Prices!$A$5:$A$82,0)),1)*INDEX(Prices!$L$5:$L$82,MATCH(C11,Prices!$A$5:$A$82,0)),J11)) -> 4.95 | M11: =IFERROR(IF(INDEX(Prices!$O$5:$O$82,MATCH(C11,Prices!$A$5:$A$82,0))="","",HYPERLINK(INDEX(Prices!$O$5:$O$82,MATCH(C11,Prices!$A$5:$A$82,0)),INDEX(Prices!$D$5:$D$82,MATCH(C11,Prices!$A$5:$A$82,0)))),"") -> BC Robotics
A12: Power | B12: Inline blade-fuse holder + 5 A blade | C12: fuseholder | D12: 1 | E12: =INDEX(Prices!$I$5:$I$82,MATCH(C12,Prices!$A$5:$A$82,0)) -> 6.945 | F12: =D12*E12 -> 6.945 | G12: =INDEX(Prices!$E$5:$E$82,MATCH(C12,Prices!$A$5:$A$82,0)) -> 2 | H12: =IF(D12<=0,0,CEILING(D12/G12,1)) -> 1 | I12: =INDEX(Prices!$H$5:$H$82,MATCH(C12,Prices!$A$5:$A$82,0)) -> 13.89 | J12: =H12*I12 -> 13.89 | K12: =IF(D12<=0,0,IF(ISNUMBER(INDEX(Prices!$L$5:$L$82,MATCH(C12,Prices!$A$5:$A$82,0))),CEILING(D12/INDEX(Prices!$K$5:$K$82,MATCH(C12,Prices!$A$5:$A$82,0)),1)*INDEX(Prices!$L$5:$L$82,MATCH(C12,Prices!$A$5:$A$82,0)),J12)) -> 13.89 | M12: =IFERROR(IF(INDEX(Prices!$O$5:$O$82,MATCH(C12,Prices!$A$5:$A$82,0))="","",HYPERLINK(INDEX(Prices!$O$5:$O$82,MATCH(C12,Prices!$A$5:$A$82,0)),INDEX(Prices!$D$5:$D$82,MATCH(C12,Prices!$A$5:$A$82,0)))),"") -> BC Robotics + Partsource
A13: Power | B13: Power bus: stripboard ≈ 50 × 30 mm + 3-pin male headers | C13: stripboard | D13: 1 | E13: =INDEX(Prices!$I$5:$I$82,MATCH(C13,Prices!$A$5:$A$82,0)) -> 7.54 | F13: =D13*E13 -> 7.54 | G13: =INDEX(Prices!$E$5:$E$82,MATCH(C13,Prices!$A$5:$A$82,0)) -> 1 | H13: =IF(D13<=0,0,CEILING(D13/G13,1)) -> 1 | I13: =INDEX(Prices!$H$5:$H$82,MATCH(C13,Prices!$A$5:$A$82,0)) -> 7.54 | J13: =H13*I13 -> 7.54 | K13: =IF(D13<=0,0,IF(ISNUMBER(INDEX(Prices!$L$5:$L$82,MATCH(C13,Prices!$A$5:$A$82,0))),CEILING(D13/INDEX(Prices!$K$5:$K$82,MATCH(C13,Prices!$A$5:$A$82,0)),1)*INDEX(Prices!$L$5:$L$82,MATCH(C13,Prices!$A$5:$A$82,0)),J13)) -> 6 | L13: Or a 5-way terminal strip | M13: =IFERROR(IF(INDEX(Prices!$O$5:$O$82,MATCH(C13,Prices!$A$5:$A$82,0))="","",HYPERLINK(INDEX(Prices!$O$5:$O$82,MATCH(C13,Prices!$A$5:$A$82,0)),INDEX(Prices!$D$5:$D$82,MATCH(C13,Prices!$A$5:$A$82,0)))),"") -> Solarbotics (Calgary AB) + Universal-Solder / CANADUINO
A14: Power | B14: Silicone wire 18-20 AWG, red and black, 1 m | C14: wire18 | D14: 1 | E14: =INDEX(Prices!$I$5:$I$82,MATCH(C14,Prices!$A$5:$A$82,0)) -> 5.62 | F14: =D14*E14 -> 5.62 | G14: =INDEX(Prices!$E$5:$E$82,MATCH(C14,Prices!$A$5:$A$82,0)) -> 1 | H14: =IF(D14<=0,0,CEILING(D14/G14,1)) -> 1 | I14: =INDEX(Prices!$H$5:$H$82,MATCH(C14,Prices!$A$5:$A$82,0)) -> 5.62 | J14: =H14*I14 -> 5.62 | K14: =IF(D14<=0,0,IF(ISNUMBER(INDEX(Prices!$L$5:$L$82,MATCH(C14,Prices!$A$5:$A$82,0))),CEILING(D14/INDEX(Prices!$K$5:$K$82,MATCH(C14,Prices!$A$5:$A$82,0)),1)*INDEX(Prices!$L$5:$L$82,MATCH(C14,Prices!$A$5:$A$82,0)),J14)) -> 5.62 | L14: Servo power never runs through Dupont jumpers | M14: =IFERROR(IF(INDEX(Prices!$O$5:$O$82,MATCH(C14,Prices!$A$5:$A$82,0))="","",HYPERLINK(INDEX(Prices!$O$5:$O$82,MATCH(C14,Prices!$A$5:$A$82,0)),INDEX(Prices!$D$5:$D$82,MATCH(C14,Prices!$A$5:$A$82,0)))),"") -> RobotShop CA
A15: Power | B15: 1000 µF electrolytic capacitor | C15: capkit.1000uF | D15: 1 | E15: =INDEX(Prices!$I$5:$I$82,MATCH(C15,Prices!$A$5:$A$82,0)) -> 0.71 | F15: =D15*E15 -> 0.71 | G15: =INDEX(Prices!$E$5:$E$82,MATCH(C15,Prices!$A$5:$A$82,0)) -> 1 | H15: =IF(D15<=0,0,CEILING(D15/G15,1)) -> 1 | I15: =INDEX(Prices!$H$5:$H$82,MATCH(C15,Prices!$A$5:$A$82,0)) -> 0.71 | J15: =H15*I15 -> 0.71 | K15: =IF(D15<=0,0,IF(ISNUMBER(INDEX(Prices!$L$5:$L$82,MATCH(C15,Prices!$A$5:$A$82,0))),CEILING(D15/INDEX(Prices!$K$5:$K$82,MATCH(C15,Prices!$A$5:$A$82,0)),1)*INDEX(Prices!$L$5:$L$82,MATCH(C15,Prices!$A$5:$A$82,0)),J15)) -> 0.71 | M15: =IFERROR(IF(INDEX(Prices!$O$5:$O$82,MATCH(C15,Prices!$A$5:$A$82,0))="","",HYPERLINK(INDEX(Prices!$O$5:$O$82,MATCH(C15,Prices!$A$5:$A$82,0)),INDEX(Prices!$D$5:$D$82,MATCH(C15,Prices!$A$5:$A$82,0)))),"") -> RobotShop (Canada)
A16: Power | B16: SMBJ6.5A TVS diode (optional) | C16: tvs | D16: 1 | E16: =INDEX(Prices!$I$5:$I$82,MATCH(C16,Prices!$A$5:$A$82,0)) -> 0.72 | F16: =D16*E16 -> 0.72 | G16: =INDEX(Prices!$E$5:$E$82,MATCH(C16,Prices!$A$5:$A$82,0)) -> 1 | H16: =IF(D16<=0,0,CEILING(D16/G16,1)) -> 1 | I16: =INDEX(Prices!$H$5:$H$82,MATCH(C16,Prices!$A$5:$A$82,0)) -> 0.72 | J16: =H16*I16 -> 0.72 | K16: =IF(D16<=0,0,IF(ISNUMBER(INDEX(Prices!$L$5:$L$82,MATCH(C16,Prices!$A$5:$A$82,0))),CEILING(D16/INDEX(Prices!$K$5:$K$82,MATCH(C16,Prices!$A$5:$A$82,0)),1)*INDEX(Prices!$L$5:$L$82,MATCH(C16,Prices!$A$5:$A$82,0)),J16)) -> 0.72 | L16: Optional | M16: =IFERROR(IF(INDEX(Prices!$O$5:$O$82,MATCH(C16,Prices!$A$5:$A$82,0))="","",HYPERLINK(INDEX(Prices!$O$5:$O$82,MATCH(C16,Prices!$A$5:$A$82,0)),INDEX(Prices!$D$5:$D$82,MATCH(C16,Prices!$A$5:$A$82,0)))),"") -> Mouser (Canada)
A17: Wiring | B17: Servo extension 50 cm (claw, wrist) | C17: servoext50 | D17: 2 | E17: =INDEX(Prices!$I$5:$I$82,MATCH(C17,Prices!$A$5:$A$82,0)) -> 1.36 | F17: =D17*E17 -> 2.72 | G17: =INDEX(Prices!$E$5:$E$82,MATCH(C17,Prices!$A$5:$A$82,0)) -> 1 | H17: =IF(D17<=0,0,CEILING(D17/G17,1)) -> 2 | I17: =INDEX(Prices!$H$5:$H$82,MATCH(C17,Prices!$A$5:$A$82,0)) -> 1.36 | J17: =H17*I17 -> 2.72 | K17: =IF(D17<=0,0,IF(ISNUMBER(INDEX(Prices!$L$5:$L$82,MATCH(C17,Prices!$A$5:$A$82,0))),CEILING(D17/INDEX(Prices!$K$5:$K$82,MATCH(C17,Prices!$A$5:$A$82,0)),1)*INDEX(Prices!$L$5:$L$82,MATCH(C17,Prices!$A$5:$A$82,0)),J17)) -> 2.72 | L17: Priced at 60 cm | M17: =IFERROR(IF(INDEX(Prices!$O$5:$O$82,MATCH(C17,Prices!$A$5:$A$82,0))="","",HYPERLINK(INDEX(Prices!$O$5:$O$82,MATCH(C17,Prices!$A$5:$A$82,0)),INDEX(Prices!$D$5:$D$82,MATCH(C17,Prices!$A$5:$A$82,0)))),"") -> RobotShop (Canada)
A18: Wiring | B18: Servo extension 30 cm (elbow) | C18: servoext30 | D18: 1 | E18: =INDEX(Prices!$I$5:$I$82,MATCH(C18,Prices!$A$5:$A$82,0)) -> 3.06 | F18: =D18*E18 -> 3.06 | G18: =INDEX(Prices!$E$5:$E$82,MATCH(C18,Prices!$A$5:$A$82,0)) -> 1 | H18: =IF(D18<=0,0,CEILING(D18/G18,1)) -> 1 | I18: =INDEX(Prices!$H$5:$H$82,MATCH(C18,Prices!$A$5:$A$82,0)) -> 3.06 | J18: =H18*I18 -> 3.06 | K18: =IF(D18<=0,0,IF(ISNUMBER(INDEX(Prices!$L$5:$L$82,MATCH(C18,Prices!$A$5:$A$82,0))),CEILING(D18/INDEX(Prices!$K$5:$K$82,MATCH(C18,Prices!$A$5:$A$82,0)),1)*INDEX(Prices!$L$5:$L$82,MATCH(C18,Prices!$A$5:$A$82,0)),J18)) -> 3.06 | M18: =IFERROR(IF(INDEX(Prices!$O$5:$O$82,MATCH(C18,Prices!$A$5:$A$82,0))="","",HYPERLINK(INDEX(Prices!$O$5:$O$82,MATCH(C18,Prices!$A$5:$A$82,0)),INDEX(Prices!$D$5:$D$82,MATCH(C18,Prices!$A$5:$A$82,0)))),"") -> RobotShop (Canada)
A19: Wiring | B19: Jumper wires F-F (signals only) | C19: jumpers.ff | D19: 5 | E19: =INDEX(Prices!$I$5:$I$82,MATCH(C19,Prices!$A$5:$A$82,0)) -> 0.1425 | F19: =D19*E19 -> 0.7125 | G19: =INDEX(Prices!$E$5:$E$82,MATCH(C19,Prices!$A$5:$A$82,0)) -> 40 | H19: =IF(D19<=0,0,CEILING(D19/G19,1)) -> 1 | I19: =INDEX(Prices!$H$5:$H$82,MATCH(C19,Prices!$A$5:$A$82,0)) -> 5.7 | J19: =H19*I19 -> 5.7 | K19: =IF(D19<=0,0,IF(ISNUMBER(INDEX(Prices!$L$5:$L$82,MATCH(C19,Prices!$A$5:$A$82,0))),CEILING(D19/INDEX(Prices!$K$5:$K$82,MATCH(C19,Prices!$A$5:$A$82,0)),1)*INDEX(Prices!$L$5:$L$82,MATCH(C19,Prices!$A$5:$A$82,0)),J19)) -> 5.7 | M19: =IFERROR(IF(INDEX(Prices!$O$5:$O$82,MATCH(C19,Prices!$A$5:$A$82,0))="","",HYPERLINK(INDEX(Prices!$O$5:$O$82,MATCH(C19,Prices!$A$5:$A$82,0)),INDEX(Prices!$D$5:$D$82,MATCH(C19,Prices!$A$5:$A$82,0)))),"") -> RobotShop (Canada)
A20: Wiring | B20: 10 kΩ pull-down resistors (optional) | C20: reskit.kit | D20: 0.1 | E20: =INDEX(Prices!$I$5:$I$82,MATCH(C20,Prices!$A$5:$A$82,0)) -> 12.95 | F20: =D20*E20 -> 1.295 | G20: =INDEX(Prices!$E$5:$E$82,MATCH(C20,Prices!$A$5:$A$82,0)) -> 1 | H20: =IF(D20<=0,0,CEILING(D20/G20,1)) -> 1 | I20: =INDEX(Prices!$H$5:$H$82,MATCH(C20,Prices!$A$5:$A$82,0)) -> 12.95 | J20: =H20*I20 -> 12.95 | K20: =IF(D20<=0,0,IF(ISNUMBER(INDEX(Prices!$L$5:$L$82,MATCH(C20,Prices!$A$5:$A$82,0))),CEILING(D20/INDEX(Prices!$K$5:$K$82,MATCH(C20,Prices!$A$5:$A$82,0)),1)*INDEX(Prices!$L$5:$L$82,MATCH(C20,Prices!$A$5:$A$82,0)),J20)) -> 12.95 | L20: Share of a resistor kit | M20: =IFERROR(IF(INDEX(Prices!$O$5:$O$82,MATCH(C20,Prices!$A$5:$A$82,0))="","",HYPERLINK(INDEX(Prices!$O$5:$O$82,MATCH(C20,Prices!$A$5:$A$82,0)),INDEX(Prices!$D$5:$D$82,MATCH(C20,Prices!$A$5:$A$82,0)))),"") -> BC Robotics
A21: Wiring | B21: Right-angle micro-USB/USB-C cable for the ESP32 | C21: usbra | D21: 1 | E21: =INDEX(Prices!$I$5:$I$82,MATCH(C21,Prices!$A$5:$A$82,0)) -> 23.99 | F21: =D21*E21 -> 23.99 | G21: =INDEX(Prices!$E$5:$E$82,MATCH(C21,Prices!$A$5:$A$82,0)) -> 1 | H21: =IF(D21<=0,0,CEILING(D21/G21,1)) -> 1 | I21: =INDEX(Prices!$H$5:$H$82,MATCH(C21,Prices!$A$5:$A$82,0)) -> 23.99 | J21: =H21*I21 -> 23.99 | K21: =IF(D21<=0,0,IF(ISNUMBER(INDEX(Prices!$L$5:$L$82,MATCH(C21,Prices!$A$5:$A$82,0))),CEILING(D21/INDEX(Prices!$K$5:$K$82,MATCH(C21,Prices!$A$5:$A$82,0)),1)*INDEX(Prices!$L$5:$L$82,MATCH(C21,Prices!$A$5:$A$82,0)),J21)) -> 8 | M21: =IFERROR(IF(INDEX(Prices!$O$5:$O$82,MATCH(C21,Prices!$A$5:$A$82,0))="","",HYPERLINK(INDEX(Prices!$O$5:$O$82,MATCH(C21,Prices!$A$5:$A$82,0)),INDEX(Prices!$D$5:$D$82,MATCH(C21,Prices!$A$5:$A$82,0)))),"") -> Staples Canada
A22: Wiring | B22: Thin right-angle USB-C to USB-A cable, 2 m (Brio) | C22: usbc | D22: 1 | E22: =INDEX(Prices!$I$5:$I$82,MATCH(C22,Prices!$A$5:$A$82,0)) -> 15 | F22: =D22*E22 -> 15 | G22: =INDEX(Prices!$E$5:$E$82,MATCH(C22,Prices!$A$5:$A$82,0)) -> 1 | H22: =IF(D22<=0,0,CEILING(D22/G22,1)) -> 1 | I22: =INDEX(Prices!$H$5:$H$82,MATCH(C22,Prices!$A$5:$A$82,0)) -> 15 | J22: =H22*I22 -> 15 | K22: =IF(D22<=0,0,IF(ISNUMBER(INDEX(Prices!$L$5:$L$82,MATCH(C22,Prices!$A$5:$A$82,0))),CEILING(D22/INDEX(Prices!$K$5:$K$82,MATCH(C22,Prices!$A$5:$A$82,0)),1)*INDEX(Prices!$L$5:$L$82,MATCH(C22,Prices!$A$5:$A$82,0)),J22)) -> 15 | L22: Priced for a straight 2 m cable | M22: =IFERROR(IF(INDEX(Prices!$O$5:$O$82,MATCH(C22,Prices!$A$5:$A$82,0))="","",HYPERLINK(INDEX(Prices!$O$5:$O$82,MATCH(C22,Prices!$A$5:$A$82,0)),INDEX(Prices!$D$5:$D$82,MATCH(C22,Prices!$A$5:$A$82,0)))),"") -> RobotShop (Canada)
A23: Wiring | B23: Zip ties, adhesive tie mounts | C23: ziptie | D23: 10 | E23: =INDEX(Prices!$I$5:$I$82,MATCH(C23,Prices!$A$5:$A$82,0)) -> 0.0599 | F23: =D23*E23 -> 0.599 | G23: =INDEX(Prices!$E$5:$E$82,MATCH(C23,Prices!$A$5:$A$82,0)) -> 100 | H23: =IF(D23<=0,0,CEILING(D23/G23,1)) -> 1 | I23: =INDEX(Prices!$H$5:$H$82,MATCH(C23,Prices!$A$5:$A$82,0)) -> 5.99 | J23: =H23*I23 -> 5.99 | K23: =IF(D23<=0,0,IF(ISNUMBER(INDEX(Prices!$L$5:$L$82,MATCH(C23,Prices!$A$5:$A$82,0))),CEILING(D23/INDEX(Prices!$K$5:$K$82,MATCH(C23,Prices!$A$5:$A$82,0)),1)*INDEX(Prices!$L$5:$L$82,MATCH(C23,Prices!$A$5:$A$82,0)),J23)) -> 5.99 | M23: =IFERROR(IF(INDEX(Prices!$O$5:$O$82,MATCH(C23,Prices!$A$5:$A$82,0))="","",HYPERLINK(INDEX(Prices!$O$5:$O$82,MATCH(C23,Prices!$A$5:$A$82,0)),INDEX(Prices!$D$5:$D$82,MATCH(C23,Prices!$A$5:$A$82,0)))),"") -> Princess Auto
A24: Wiring | B24: Adhesive cable-tie mounts | C24: tiemount | D24: 2 | E24: =INDEX(Prices!$I$5:$I$82,MATCH(C24,Prices!$A$5:$A$82,0)) -> 0.09 | F24: =D24*E24 -> 0.18 | G24: =INDEX(Prices!$E$5:$E$82,MATCH(C24,Prices!$A$5:$A$82,0)) -> 100 | H24: =IF(D24<=0,0,CEILING(D24/G24,1)) -> 1 | I24: =INDEX(Prices!$H$5:$H$82,MATCH(C24,Prices!$A$5:$A$82,0)) -> 9 | J24: =H24*I24 -> 9 | K24: =IF(D24<=0,0,IF(ISNUMBER(INDEX(Prices!$L$5:$L$82,MATCH(C24,Prices!$A$5:$A$82,0))),CEILING(D24/INDEX(Prices!$K$5:$K$82,MATCH(C24,Prices!$A$5:$A$82,0)),1)*INDEX(Prices!$L$5:$L$82,MATCH(C24,Prices!$A$5:$A$82,0)),J24)) -> 9 | M24: =IFERROR(IF(INDEX(Prices!$O$5:$O$82,MATCH(C24,Prices!$A$5:$A$82,0))="","",HYPERLINK(INDEX(Prices!$O$5:$O$82,MATCH(C24,Prices!$A$5:$A$82,0)),INDEX(Prices!$D$5:$D$82,MATCH(C24,Prices!$A$5:$A$82,0)))),"") -> Fleet Network (Canada)
A25: Wiring | B25: Heat-shrink tubing | C25: heatshrink | D25: 0.1 | E25: =INDEX(Prices!$I$5:$I$82,MATCH(C25,Prices!$A$5:$A$82,0)) -> 12.84 | F25: =D25*E25 -> 1.284 | G25: =INDEX(Prices!$E$5:$E$82,MATCH(C25,Prices!$A$5:$A$82,0)) -> 1 | H25: =IF(D25<=0,0,CEILING(D25/G25,1)) -> 1 | I25: =INDEX(Prices!$H$5:$H$82,MATCH(C25,Prices!$A$5:$A$82,0)) -> 12.84 | J25: =H25*I25 -> 12.84 | K25: =IF(D25<=0,0,IF(ISNUMBER(INDEX(Prices!$L$5:$L$82,MATCH(C25,Prices!$A$5:$A$82,0))),CEILING(D25/INDEX(Prices!$K$5:$K$82,MATCH(C25,Prices!$A$5:$A$82,0)),1)*INDEX(Prices!$L$5:$L$82,MATCH(C25,Prices!$A$5:$A$82,0)),J25)) -> 12.84 | L25: Share of a kit | M25: =IFERROR(IF(INDEX(Prices!$O$5:$O$82,MATCH(C25,Prices!$A$5:$A$82,0))="","",HYPERLINK(INDEX(Prices!$O$5:$O$82,MATCH(C25,Prices!$A$5:$A$82,0)),INDEX(Prices!$D$5:$D$82,MATCH(C25,Prices!$A$5:$A$82,0)))),"") -> RobotShop (Canada)
A26: Fasteners | B26: M3 × 14 socket head (horn clamps) and other M3 machine screws | C26: m3shcs | D26: 0.05 | E26: =INDEX(Prices!$I$5:$I$82,MATCH(C26,Prices!$A$5:$A$82,0)) -> 24 | F26: =D26*E26 -> 1.2 | G26: =INDEX(Prices!$E$5:$E$82,MATCH(C26,Prices!$A$5:$A$82,0)) -> 1 | H26: =IF(D26<=0,0,CEILING(D26/G26,1)) -> 1 | I26: =INDEX(Prices!$H$5:$H$82,MATCH(C26,Prices!$A$5:$A$82,0)) -> 24 | J26: =H26*I26 -> 24 | K26: =IF(D26<=0,0,IF(ISNUMBER(INDEX(Prices!$L$5:$L$82,MATCH(C26,Prices!$A$5:$A$82,0))),CEILING(D26/INDEX(Prices!$K$5:$K$82,MATCH(C26,Prices!$A$5:$A$82,0)),1)*INDEX(Prices!$L$5:$L$82,MATCH(C26,Prices!$A$5:$A$82,0)),J26)) -> 24 | L26: Share of a 240-piece kit | M26: =IFERROR(IF(INDEX(Prices!$O$5:$O$82,MATCH(C26,Prices!$A$5:$A$82,0))="","",HYPERLINK(INDEX(Prices!$O$5:$O$82,MATCH(C26,Prices!$A$5:$A$82,0)),INDEX(Prices!$D$5:$D$82,MATCH(C26,Prices!$A$5:$A$82,0)))),"") -> Spool3D
A27: Fasteners | B27: M3 large washers Ø9 | C27: m3washer.din9021 | D27: 3 | E27: =INDEX(Prices!$I$5:$I$82,MATCH(C27,Prices!$A$5:$A$82,0)) -> 0.095 | F27: =D27*E27 -> 0.285 | G27: =INDEX(Prices!$E$5:$E$82,MATCH(C27,Prices!$A$5:$A$82,0)) -> 10 | H27: =IF(D27<=0,0,CEILING(D27/G27,1)) -> 1 | I27: =INDEX(Prices!$H$5:$H$82,MATCH(C27,Prices!$A$5:$A$82,0)) -> 0.95 | J27: =H27*I27 -> 0.95 | K27: =IF(D27<=0,0,IF(ISNUMBER(INDEX(Prices!$L$5:$L$82,MATCH(C27,Prices!$A$5:$A$82,0))),CEILING(D27/INDEX(Prices!$K$5:$K$82,MATCH(C27,Prices!$A$5:$A$82,0)),1)*INDEX(Prices!$L$5:$L$82,MATCH(C27,Prices!$A$5:$A$82,0)),J27)) -> 0.95 | M27: =IFERROR(IF(INDEX(Prices!$O$5:$O$82,MATCH(C27,Prices!$A$5:$A$82,0))="","",HYPERLINK(INDEX(Prices!$O$5:$O$82,MATCH(C27,Prices!$A$5:$A$82,0)),INDEX(Prices!$D$5:$D$82,MATCH(C27,Prices!$A$5:$A$82,0)))),"") -> RobotShop CA
A28: Fasteners | B28: M3 washers Ø7 (MG996R tab screws) | C28: m3washer.iso7089 | D28: 12 | E28: =INDEX(Prices!$I$5:$I$82,MATCH(C28,Prices!$A$5:$A$82,0)) -> 0.04875 | F28: =D28*E28 -> 0.585 | G28: =INDEX(Prices!$E$5:$E$82,MATCH(C28,Prices!$A$5:$A$82,0)) -> 40 | H28: =IF(D28<=0,0,CEILING(D28/G28,1)) -> 1 | I28: =INDEX(Prices!$H$5:$H$82,MATCH(C28,Prices!$A$5:$A$82,0)) -> 1.95 | J28: =H28*I28 -> 1.95 | K28: =IF(D28<=0,0,IF(ISNUMBER(INDEX(Prices!$L$5:$L$82,MATCH(C28,Prices!$A$5:$A$82,0))),CEILING(D28/INDEX(Prices!$K$5:$K$82,MATCH(C28,Prices!$A$5:$A$82,0)),1)*INDEX(Prices!$L$5:$L$82,MATCH(C28,Prices!$A$5:$A$82,0)),J28)) -> 1.95 | M28: =IFERROR(IF(INDEX(Prices!$O$5:$O$82,MATCH(C28,Prices!$A$5:$A$82,0))="","",HYPERLINK(INDEX(Prices!$O$5:$O$82,MATCH(C28,Prices!$A$5:$A$82,0)),INDEX(Prices!$D$5:$D$82,MATCH(C28,Prices!$A$5:$A$82,0)))),"") -> BC Robotics
A29: Fasteners | B29: Self-tapping screws M2-M3, 6-12 mm (≈33) | C29: selftap | D29: 33 | E29: =INDEX(Prices!$I$5:$I$82,MATCH(C29,Prices!$A$5:$A$82,0)) -> 0.149 | F29: =D29*E29 -> 4.917 | G29: =INDEX(Prices!$E$5:$E$82,MATCH(C29,Prices!$A$5:$A$82,0)) -> 10 | H29: =IF(D29<=0,0,CEILING(D29/G29,1)) -> 4 | I29: =INDEX(Prices!$H$5:$H$82,MATCH(C29,Prices!$A$5:$A$82,0)) -> 1.49 | J29: =H29*I29 -> 5.96 | K29: =IF(D29<=0,0,IF(ISNUMBER(INDEX(Prices!$L$5:$L$82,MATCH(C29,Prices!$A$5:$A$82,0))),CEILING(D29/INDEX(Prices!$K$5:$K$82,MATCH(C29,Prices!$A$5:$A$82,0)),1)*INDEX(Prices!$L$5:$L$82,MATCH(C29,Prices!$A$5:$A$82,0)),J29)) -> 5.96 | L29: Tab, cover, ring, cradle and horn screws | M29: =IFERROR(IF(INDEX(Prices!$O$5:$O$82,MATCH(C29,Prices!$A$5:$A$82,0))="","",HYPERLINK(INDEX(Prices!$O$5:$O$82,MATCH(C29,Prices!$A$5:$A$82,0)),INDEX(Prices!$D$5:$D$82,MATCH(C29,Prices!$A$5:$A$82,0)))),"") -> Canada Robotix
A30: Fasteners | B30: M2 × 12 machine screws (wrist and pinion clamps) | C30: m2kit | D30: 2 | E30: =INDEX(Prices!$I$5:$I$82,MATCH(C30,Prices!$A$5:$A$82,0)) -> 0.1475 | F30: =D30*E30 -> 0.295 | G30: =INDEX(Prices!$E$5:$E$82,MATCH(C30,Prices!$A$5:$A$82,0)) -> 20 | H30: =IF(D30<=0,0,CEILING(D30/G30,1)) -> 1 | I30: =INDEX(Prices!$H$5:$H$82,MATCH(C30,Prices!$A$5:$A$82,0)) -> 2.95 | J30: =H30*I30 -> 2.95 | K30: =IF(D30<=0,0,IF(ISNUMBER(INDEX(Prices!$L$5:$L$82,MATCH(C30,Prices!$A$5:$A$82,0))),CEILING(D30/INDEX(Prices!$K$5:$K$82,MATCH(C30,Prices!$A$5:$A$82,0)),1)*INDEX(Prices!$L$5:$L$82,MATCH(C30,Prices!$A$5:$A$82,0)),J30)) -> 2.95 | M30: =IFERROR(IF(INDEX(Prices!$O$5:$O$82,MATCH(C30,Prices!$A$5:$A$82,0))="","",HYPERLINK(INDEX(Prices!$O$5:$O$82,MATCH(C30,Prices!$A$5:$A$82,0)),INDEX(Prices!$D$5:$D$82,MATCH(C30,Prices!$A$5:$A$82,0)))),"") -> BC Robotics
A31: Fasteners | B31: M2 washers Ø6 | C31: m2washer | D31: 2 | E31: =INDEX(Prices!$I$5:$I$82,MATCH(C31,Prices!$A$5:$A$82,0)) -> 0.095 | F31: =D31*E31 -> 0.19 | G31: =INDEX(Prices!$E$5:$E$82,MATCH(C31,Prices!$A$5:$A$82,0)) -> 10 | H31: =IF(D31<=0,0,CEILING(D31/G31,1)) -> 1 | I31: =INDEX(Prices!$H$5:$H$82,MATCH(C31,Prices!$A$5:$A$82,0)) -> 0.95 | J31: =H31*I31 -> 0.95 | K31: =IF(D31<=0,0,IF(ISNUMBER(INDEX(Prices!$L$5:$L$82,MATCH(C31,Prices!$A$5:$A$82,0))),CEILING(D31/INDEX(Prices!$K$5:$K$82,MATCH(C31,Prices!$A$5:$A$82,0)),1)*INDEX(Prices!$L$5:$L$82,MATCH(C31,Prices!$A$5:$A$82,0)),J31)) -> 4 | M31: =IFERROR(IF(INDEX(Prices!$O$5:$O$82,MATCH(C31,Prices!$A$5:$A$82,0))="","",HYPERLINK(INDEX(Prices!$O$5:$O$82,MATCH(C31,Prices!$A$5:$A$82,0)),INDEX(Prices!$D$5:$D$82,MATCH(C31,Prices!$A$5:$A$82,0)))),"") -> RobotShop CA
A32: Fasteners | B32: #4 × 2 in wood screws (desk mounting) | C32: woodscrew | D32: 4 | E32: =INDEX(Prices!$I$5:$I$82,MATCH(C32,Prices!$A$5:$A$82,0)) -> 0.16 | F32: =D32*E32 -> 0.64 | G32: =INDEX(Prices!$E$5:$E$82,MATCH(C32,Prices!$A$5:$A$82,0)) -> 25 | H32: =IF(D32<=0,0,CEILING(D32/G32,1)) -> 1 | I32: =INDEX(Prices!$H$5:$H$82,MATCH(C32,Prices!$A$5:$A$82,0)) -> 4 | J32: =H32*I32 -> 4 | K32: =IF(D32<=0,0,IF(ISNUMBER(INDEX(Prices!$L$5:$L$82,MATCH(C32,Prices!$A$5:$A$82,0))),CEILING(D32/INDEX(Prices!$K$5:$K$82,MATCH(C32,Prices!$A$5:$A$82,0)),1)*INDEX(Prices!$L$5:$L$82,MATCH(C32,Prices!$A$5:$A$82,0)),J32)) -> 4 | L32: Or a 200 × 200 mm board with rubber feet | M32: =IFERROR(IF(INDEX(Prices!$O$5:$O$82,MATCH(C32,Prices!$A$5:$A$82,0))="","",HYPERLINK(INDEX(Prices!$O$5:$O$82,MATCH(C32,Prices!$A$5:$A$82,0)),INDEX(Prices!$D$5:$D$82,MATCH(C32,Prices!$A$5:$A$82,0)))),"")
A33: Fasteners | B33: 1/4"-20 × 5/16" thumb screw (camera) | C33: thumbscrew | D33: 1 | E33: =INDEX(Prices!$I$5:$I$82,MATCH(C33,Prices!$A$5:$A$82,0)) -> 7.94 | F33: =D33*E33 -> 7.94 | G33: =INDEX(Prices!$E$5:$E$82,MATCH(C33,Prices!$A$5:$A$82,0)) -> 1 | H33: =IF(D33<=0,0,CEILING(D33/G33,1)) -> 1 | I33: =INDEX(Prices!$H$5:$H$82,MATCH(C33,Prices!$A$5:$A$82,0)) -> 7.94 | J33: =H33*I33 -> 7.94 | K33: =IF(D33<=0,0,IF(ISNUMBER(INDEX(Prices!$L$5:$L$82,MATCH(C33,Prices!$A$5:$A$82,0))),CEILING(D33/INDEX(Prices!$K$5:$K$82,MATCH(C33,Prices!$A$5:$A$82,0)),1)*INDEX(Prices!$L$5:$L$82,MATCH(C33,Prices!$A$5:$A$82,0)),J33)) -> 3 | M33: =IFERROR(IF(INDEX(Prices!$O$5:$O$82,MATCH(C33,Prices!$A$5:$A$82,0))="","",HYPERLINK(INDEX(Prices!$O$5:$O$82,MATCH(C33,Prices!$A$5:$A$82,0)),INDEX(Prices!$D$5:$D$82,MATCH(C33,Prices!$A$5:$A$82,0)))),"") -> KBC Tools & Machinery (Mississauga ON)
A34: Supplies | B34: PTFE tape (turntable ring) | C34: ptfe | D34: 1 | E34: =INDEX(Prices!$I$5:$I$82,MATCH(C34,Prices!$A$5:$A$82,0)) -> 0.99 | F34: =D34*E34 -> 0.99 | G34: =INDEX(Prices!$E$5:$E$82,MATCH(C34,Prices!$A$5:$A$82,0)) -> 1 | H34: =IF(D34<=0,0,CEILING(D34/G34,1)) -> 1 | I34: =INDEX(Prices!$H$5:$H$82,MATCH(C34,Prices!$A$5:$A$82,0)) -> 0.99 | J34: =H34*I34 -> 0.99 | K34: =IF(D34<=0,0,IF(ISNUMBER(INDEX(Prices!$L$5:$L$82,MATCH(C34,Prices!$A$5:$A$82,0))),CEILING(D34/INDEX(Prices!$K$5:$K$82,MATCH(C34,Prices!$A$5:$A$82,0)),1)*INDEX(Prices!$L$5:$L$82,MATCH(C34,Prices!$A$5:$A$82,0)),J34)) -> 0.99 | M34: =IFERROR(IF(INDEX(Prices!$O$5:$O$82,MATCH(C34,Prices!$A$5:$A$82,0))="","",HYPERLINK(INDEX(Prices!$O$5:$O$82,MATCH(C34,Prices!$A$5:$A$82,0)),INDEX(Prices!$D$5:$D$82,MATCH(C34,Prices!$A$5:$A$82,0)))),"") -> Princess Auto
A35: Supplies | B35: Rubber feet (board option) | C35: rubberfeet | D35: 4 | E35: =INDEX(Prices!$I$5:$I$82,MATCH(C35,Prices!$A$5:$A$82,0)) -> 0.25 | F35: =D35*E35 -> 1 | G35: =INDEX(Prices!$E$5:$E$82,MATCH(C35,Prices!$A$5:$A$82,0)) -> 4 | H35: =IF(D35<=0,0,CEILING(D35/G35,1)) -> 1 | I35: =INDEX(Prices!$H$5:$H$82,MATCH(C35,Prices!$A$5:$A$82,0)) -> 1 | J35: =H35*I35 -> 1 | K35: =IF(D35<=0,0,IF(ISNUMBER(INDEX(Prices!$L$5:$L$82,MATCH(C35,Prices!$A$5:$A$82,0))),CEILING(D35/INDEX(Prices!$K$5:$K$82,MATCH(C35,Prices!$A$5:$A$82,0)),1)*INDEX(Prices!$L$5:$L$82,MATCH(C35,Prices!$A$5:$A$82,0)),J35)) -> 1 | M35: =IFERROR(IF(INDEX(Prices!$O$5:$O$82,MATCH(C35,Prices!$A$5:$A$82,0))="","",HYPERLINK(INDEX(Prices!$O$5:$O$82,MATCH(C35,Prices!$A$5:$A$82,0)),INDEX(Prices!$D$5:$D$82,MATCH(C35,Prices!$A$5:$A$82,0)))),"") -> BC Robotics
A36: Supplies | B36: CA glue (horn in the pinion) | C36: consumables.ca | D36: 0.5 | E36: =INDEX(Prices!$I$5:$I$82,MATCH(C36,Prices!$A$5:$A$82,0)) -> 4.995 | F36: =D36*E36 -> 2.4975 | G36: =INDEX(Prices!$E$5:$E$82,MATCH(C36,Prices!$A$5:$A$82,0)) -> 2 | H36: =IF(D36<=0,0,CEILING(D36/G36,1)) -> 1 | I36: =INDEX(Prices!$H$5:$H$82,MATCH(C36,Prices!$A$5:$A$82,0)) -> 9.99 | J36: =H36*I36 -> 9.99 | K36: =IF(D36<=0,0,IF(ISNUMBER(INDEX(Prices!$L$5:$L$82,MATCH(C36,Prices!$A$5:$A$82,0))),CEILING(D36/INDEX(Prices!$K$5:$K$82,MATCH(C36,Prices!$A$5:$A$82,0)),1)*INDEX(Prices!$L$5:$L$82,MATCH(C36,Prices!$A$5:$A$82,0)),J36)) -> 9.99 | M36: =IFERROR(IF(INDEX(Prices!$O$5:$O$82,MATCH(C36,Prices!$A$5:$A$82,0))="","",HYPERLINK(INDEX(Prices!$O$5:$O$82,MATCH(C36,Prices!$A$5:$A$82,0)),INDEX(Prices!$D$5:$D$82,MATCH(C36,Prices!$A$5:$A$82,0)))),"") -> Princess Auto
A38: Printing
A39: Printed | B39: PETG filament (kg) | D39: 0.418 | E39: =Summary!$C$9 -> 14.99 | F39: =D39*E39 -> 6.26582 | J39: =CEILING(D39,1)*E39 -> 14.99 | K39: =F39 -> 6.26582 | L39: Slices of 26 Oct 2026: 11 plates; claw frame and cover from their earlier slices until the fifth attempt is sliced. 'Cost to buy' counts whole 1 kg spools.
A40: Printed | B40: Print electricity (hours) | D40: 34.5 | E40: =Summary!$C$11*Summary!$C$10 -> 0.014256 | F40: =D40*E40 -> 0.491832 | J40: =D40*E40 -> 0.491832 | K40: =D40*E40 -> 0.491832 | L40: Printer power × NB Power rate (Summary sheet)
B42: Total before tax | F42: =SUM(F5:F36)+F39+F40 -> 180.41265 | J42: =SUM(J5:J36)+J39+J40 -> 278.63183 | K42: =SUM(K5:K36)+K39+K40 -> 239.02195
B43: HST | F43: =F42*Summary!$C$7 -> 27.061898 | J43: =J42*Summary!$C$7 -> 41.794775 | K43: =K42*Summary!$C$7 -> 35.853293
...

Sheet Rover
A1: Rover: bought parts and print cost
A2: Quantities come from the build guide's bill of materials. 'Value of parts used' counts only the share of each pack this robot uses; 'Cost to buy' is what you pay buying whole packs for this robot alone.
A4: Group | B4: Item | C4: Price key | D4: Qty | E4: Unit price | F4: Value of parts used | G4: Pack qty | H4: Packs to buy | I4: Pack price | J4: Cost to buy | K4: Budget cost | L4: Notes | M4: Where to buy
A5: Motors and boards | B5: N20 gearmotor 6 V ≈150:1 (LP or MP), 3 mm D-shaft 10 mm long (at least 9.6 mm) | C5: n20 | D5: 2 | E5: =INDEX(Prices!$I$5:$I$82,MATCH(C5,Prices!$A$5:$A$82,0)) -> 7.99 | F5: =D5*E5 -> 15.98 | G5: =INDEX(Prices!$E$5:$E$82,MATCH(C5,Prices!$A$5:$A$82,0)) -> 1 | H5: =IF(D5<=0,0,CEILING(D5/G5,1)) -> 2 | I5: =INDEX(Prices!$H$5:$H$82,MATCH(C5,Prices!$A$5:$A$82,0)) -> 7.99 | J5: =H5*I5 -> 15.98 | K5: =IF(D5<=0,0,IF(ISNUMBER(INDEX(Prices!$L$5:$L$82,MATCH(C5,Prices!$A$5:$A$82,0))),CEILING(D5/INDEX(Prices!$K$5:$K$82,MATCH(C5,Prices!$A$5:$A$82,0)),1)*INDEX(Prices!$L$5:$L$82,MATCH(C5,Prices!$A$5:$A$82,0)),J5)) -> 15.98 | L5: Not a 9 mm shaft (sprocket strength round 4) | M5: =IFERROR(IF(INDEX(Prices!$O$5:$O$82,MATCH(C5,Prices!$A$5:$A$82,0))="","",HYPERLINK(INDEX(Prices!$O$5:$O$82,MATCH(C5,Prices!$A$5:$A$82,0)),INDEX(Prices!$D$5:$D$82,MATCH(C5,Prices!$A$5:$A$82,0)))),"") -> Canada Robotix
A6: Motors and boards | B6: Pololu #1996 aluminium hub, 3 mm (2-pack) | C6: hub1996 | D6: 1 | E6: =INDEX(Prices!$I$5:$I$82,MATCH(C6,Prices!$A$5:$A$82,0)) -> 3.845 | F6: =D6*E6 -> 3.845 | G6: =INDEX(Prices!$E$5:$E$82,MATCH(C6,Prices!$A$5:$A$82,0)) -> 2 | H6: =IF(D6<=0,0,CEILING(D6/G6,1)) -> 1 | I6: =INDEX(Prices!$H$5:$H$82,MATCH(C6,Prices!$A$5:$A$82,0)) -> 7.69 | J6: =H6*I6 -> 7.69 | K6: =IF(D6<=0,0,IF(ISNUMBER(INDEX(Prices!$L$5:$L$82,MATCH(C6,Prices!$A$5:$A$82,0))),CEILING(D6/INDEX(Prices!$K$5:$K$82,MATCH(C6,Prices!$A$5:$A$82,0)),1)*INDEX(Prices!$L$5:$L$82,MATCH(C6,Prices!$A$5:$A$82,0)),J6)) -> 7.69 | L6: One pack | M6: =IFERROR(IF(INDEX(Prices!$O$5:$O$82,MATCH(C6,Prices!$A$5:$A$82,0))="","",HYPERLINK(INDEX(Prices!$O$5:$O$82,MATCH(C6,Prices!$A$5:$A$82,0)),INDEX(Prices!$D$5:$D$82,MATCH(C6,Prices!$A$5:$A$82,0)))),"") -> Canada Robotix
A7: Motors and boards | B7: TB6612FNG motor driver carrier | C7: tb6612 | D7: 1 | E7: =INDEX(Prices!$I$5:$I$82,MATCH(C7,Prices!$A$5:$A$82,0)) -> 7.07 | F7: =D7*E7 -> 7.07 | G7: =INDEX(Prices!$E$5:$E$82,MATCH(C7,Prices!$A$5:$A$82,0)) -> 1 | H7: =IF(D7<=0,0,CEILING(D7/G7,1)) -> 1 | I7: =INDEX(Prices!$H$5:$H$82,MATCH(C7,Prices!$A$5:$A$82,0)) -> 7.07 | J7: =H7*I7 -> 7.07 | K7: =IF(D7<=0,0,IF(ISNUMBER(INDEX(Prices!$L$5:$L$82,MATCH(C7,Prices!$A$5:$A$82,0))),CEILING(D7/INDEX(Prices!$K$5:$K$82,MATCH(C7,Prices!$A$5:$A$82,0)),1)*INDEX(Prices!$L$5:$L$82,MATCH(C7,Prices!$A$5:$A$82,0)),J7)) -> 7.07 | M7: =IFERROR(IF(INDEX(Prices!$O$5:$O$82,MATCH(C7,Prices!$A$5:$A$82,0))="","",HYPERLINK(INDEX(Prices!$O$5:$O$82,MATCH(C7,Prices!$A$5:$A$82,0)),INDEX(Prices!$D$5:$D$82,MATCH(C7,Prices!$A$5:$A$82,0)))),"") -> RobotShop CA
A8: Motors and boards | B8: ESP32 DevKit (38- or 30-pin) | C8: esp32 | D8: 1 | E8: =INDEX(Prices!$I$5:$I$82,MATCH(C8,Prices!$A$5:$A$82,0)) -> 9.86 | F8: =D8*E8 -> 9.86 | G8: =INDEX(Prices!$E$5:$E$82,MATCH(C8,Prices!$A$5:$A$82,0)) -> 1 | H8: =IF(D8<=0,0,CEILING(D8/G8,1)) -> 1 | I8: =INDEX(Prices!$H$5:$H$82,MATCH(C8,Prices!$A$5:$A$82,0)) -> 9.86 | J8: =H8*I8 -> 9.86 | K8: =IF(D8<=0,0,IF(ISNUMBER(INDEX(Prices!$L$5:$L$82,MATCH(C8,Prices!$A$5:$A$82,0))),CEILING(D8/INDEX(Prices!$K$5:$K$82,MATCH(C8,Prices!$A$5:$A$82,0)),1)*INDEX(Prices!$L$5:$L$82,MATCH(C8,Prices!$A$5:$A$82,0)),J8)) -> 9.86 | M8: =IFERROR(IF(INDEX(Prices!$O$5:$O$82,MATCH(C8,Prices!$A$5:$A$82,0))="","",HYPERLINK(INDEX(Prices!$O$5:$O$82,MATCH(C8,Prices!$A$5:$A$82,0)),INDEX(Prices!$D$5:$D$82,MATCH(C8,Prices!$A$5:$A$82,0)))),"") -> Universal-Solder (CANADUINO)
A9: Motors and boards | B9: HC-SR04 ultrasonic sensor | C9: hcsr04 | D9: 1 | E9: =INDEX(Prices!$I$5:$I$82,MATCH(C9,Prices!$A$5:$A$82,0)) -> 4.93 | F9: =D9*E9 -> 4.93 | G9: =INDEX(Prices!$E$5:$E$82,MATCH(C9,Prices!$A$5:$A$82,0)) -> 1 | H9: =IF(D9<=0,0,CEILING(D9/G9,1)) -> 1 | I9: =INDEX(Prices!$H$5:$H$82,MATCH(C9,Prices!$A$5:$A$82,0)) -> 4.93 | J9: =H9*I9 -> 4.93 | K9: =IF(D9<=0,0,IF(ISNUMBER(INDEX(Prices!$L$5:$L$82,MATCH(C9,Prices!$A$5:$A$82,0))),CEILING(D9/INDEX(Prices!$K$5:$K$82,MATCH(C9,Prices!$A$5:$A$82,0)),1)*INDEX(Prices!$L$5:$L$82,MATCH(C9,Prices!$A$5:$A$82,0)),J9)) -> 4.93 | M9: =IFERROR(IF(INDEX(Prices!$O$5:$O$82,MATCH(C9,Prices!$A$5:$A$82,0))="","",HYPERLINK(INDEX(Prices!$O$5:$O$82,MATCH(C9,Prices!$A$5:$A$82,0)),INDEX(Prices!$D$5:$D$82,MATCH(C9,Prices!$A$5:$A$82,0)))),"") -> RobotShop CA
A10: Motors and boards | B10: 170-point mini breadboard | C10: breadboard | D10: 1 | E10: =INDEX(Prices!$I$5:$I$82,MATCH(C10,Prices!$A$5:$A$82,0)) -> 2.99 | F10: =D10*E10 -> 2.99 | G10: =INDEX(Prices!$E$5:$E$82,MATCH(C10,Prices!$A$5:$A$82,0)) -> 1 | H10: =IF(D10<=0,0,CEILING(D10/G10,1)) -> 1 | I10: =INDEX(Prices!$H$5:$H$82,MATCH(C10,Prices!$A$5:$A$82,0)) -> 2.99 | J10: =H10*I10 -> 2.99 | K10: =IF(D10<=0,0,IF(ISNUMBER(INDEX(Prices!$L$5:$L$82,MATCH(C10,Prices!$A$5:$A$82,0))),CEILING(D10/INDEX(Prices!$K$5:$K$82,MATCH(C10,Prices!$A$5:$A$82,0)),1)*INDEX(Prices!$L$5:$L$82,MATCH(C10,Prices!$A$5:$A$82,0)),J10)) -> 2.99 | M10: =IFERROR(IF(INDEX(Prices!$O$5:$O$82,MATCH(C10,Prices!$A$5:$A$82,0))="","",HYPERLINK(INDEX(Prices!$O$5:$O$82,MATCH(C10,Prices!$A$5:$A$82,0)),INDEX(Prices!$D$5:$D$82,MATCH(C10,Prices!$A$5:$A$82,0)))),"") -> Canada Robotix
A11: Power | B11: 18650 Li-ion cells, protected | C11: cells18650 | D11: 2 | E11: =INDEX(Prices!$I$5:$I$82,MATCH(C11,Prices!$A$5:$A$82,0)) -> 29.95 | F11: =D11*E11 -> 59.9 | G11: =INDEX(Prices!$E$5:$E$82,MATCH(C11,Prices!$A$5:$A$82,0)) -> 1 | H11: =IF(D11<=0,0,CEILING(D11/G11,1)) -> 2 | I11: =INDEX(Prices!$H$5:$H$82,MATCH(C11,Prices!$A$5:$A$82,0)) -> 29.95 | J11: =H11*I11 -> 59.9 | K11: =IF(D11<=0,0,IF(ISNUMBER(INDEX(Prices!$L$5:$L$82,MATCH(C11,Prices!$A$5:$A$82,0))),CEILING(D11/INDEX(Prices!$K$5:$K$82,MATCH(C11,Prices!$A$5:$A$82,0)),1)*INDEX(Prices!$L$5:$L$82,MATCH(C11,Prices!$A$5:$A$82,0)),J11)) -> 20.961514 | M11: =IFERROR(IF(INDEX(Prices!$O$5:$O$82,MATCH(C11,Prices!$A$5:$A$82,0))="","",HYPERLINK(INDEX(Prices!$O$5:$O$82,MATCH(C11,Prices!$A$5:$A$82,0)),INDEX(Prices!$D$5:$D$82,MATCH(C11,Prices!$A$5:$A$82,0)))),"") -> FlashLight World (Magog QC, Canada)
A12: Power | B12: 2 × 18650 series holder (long) | C12: holder18650 | D12: 1 | E12: =INDEX(Prices!$I$5:$I$82,MATCH(C12,Prices!$A$5:$A$82,0)) -> 1.95 | F12: =D12*E12 -> 1.95 | G12: =INDEX(Prices!$E$5:$E$82,MATCH(C12,Prices!$A$5:$A$82,0)) -> 1 | H12: =IF(D12<=0,0,CEILING(D12/G12,1)) -> 1 | I12: =INDEX(Prices!$H$5:$H$82,MATCH(C12,Prices!$A$5:$A$82,0)) -> 1.95 | J12: =H12*I12 -> 1.95 | K12: =IF(D12<=0,0,IF(ISNUMBER(INDEX(Prices!$L$5:$L$82,MATCH(C12,Prices!$A$5:$A$82,0))),CEILING(D12/INDEX(Prices!$K$5:$K$82,MATCH(C12,Prices!$A$5:$A$82,0)),1)*INDEX(Prices!$L$5:$L$82,MATCH(C12,Prices!$A$5:$A$82,0)),J12)) -> 1.95 | M12: =IFERROR(IF(INDEX(Prices!$O$5:$O$82,MATCH(C12,Prices!$A$5:$A$82,0))="","",HYPERLINK(INDEX(Prices!$O$5:$O$82,MATCH(C12,Prices!$A$5:$A$82,0)),INDEX(Prices!$D$5:$D$82,MATCH(C12,Prices!$A$5:$A$82,0)))),"") -> BC Robotics
